<?xml version="1.0" encoding="UTF-8"?>
<sdf version="1.10">
  <model name="albatross">
    <pose>0 0 0.2 0 0 0</pose>
    <link name="base_link">
      <pose>0 0 0.0 0 0 -1.57</pose>
      <visual name="visual_base_link">
        <geometry>
          <mesh>
            <uri>model://albatross/meshes/Albatross.dae</uri>
          </mesh>
        </geometry>
      </visual>
      <collision name="collision_base_link">
        <geometry>
          <mesh>
            <uri>model://albatross/meshes/Albatross.dae</uri>
          </mesh>
        </geometry>
      </collision>
      <inertial>
        <pose>9.2704498225588886e-09 0.03867858926469585 0.12190761634548454 1.5707963267948966 -1.4837483016685091 1.5707963267948959</pose>
        <mass>8.9417506140315845</mass>
        <inertia>
          <ixx>4.6567457753331763</ixx>
          <ixy>0</ixy>
          <ixz>0</ixz>
          <iyy>3.0225213670373495</iyy>
          <iyz>0</iyz>
          <izz>1.6675557462777661</izz>
        </inertia>
      </inertial>
      <gravity>1</gravity>
      <velocity_decay/>
      <self_collide>0</self_collide>
      <sensor name="imu_sensor" type="imu">
        <always_on>1</always_on>
        <update_rate>250</update_rate>
      </sensor>
    </link>
    <link name="airspeed_link">
      <pose>0 0 0 0 0 0</pose>
      <inertial>
        <pose>0 0 0 0 0 0</pose>
        <mass>0.015</mass>
        <inertia>
          <ixx>1e-05</ixx>
          <ixy>0</ixy>
          <ixz>0</ixz>
          <iyy>1e-05</iyy>
          <iyz>0</iyz>
          <izz>1e-05</izz>
        </inertia>
      </inertial>
      <visual name="airspeed_visual">
        <geometry>
          <cylinder>
            <radius>0.01</radius>
            <length>0.1</length>
          </cylinder>
        </geometry>
        <material>
          <ambient>0 0 0 1.0</ambient>
          <diffuse>0 0 0 1.0</diffuse>
        </material>
      </visual>
      <sensor name="air_speed" type="air_speed">
        <always_on>1</always_on>
        <update_rate>5.0</update_rate>
        <enable_metrics>false</enable_metrics>
        <air_speed>
          <pressure>
            <noise type="gaussian">
              <mean>0</mean>
              <stddev>0.01</stddev>
            </noise>
          </pressure>
        </air_speed>
      </sensor>
    </link>
    <joint name='airspeed_joint' type='fixed'>
      <child>airspeed_link</child>
      <parent>base_link</parent>
    </joint>
    <link name="RightWheel">
      <pose relative_to="RightWheelJoint">0 0 0 0 0 0</pose>
      <inertial>
        <mass>.05</mass>
        <inertia>
          <ixx>0.00003331</ixx>
          <ixy>0</ixy>
          <ixz>0</ixz>
          <iyy>0.0000204</iyy>
          <iyz>0</iyz>
          <izz>0.0000204</izz>
        </inertia>
      </inertial>
      <gravity>true</gravity>
      <velocity_decay/>
      <visual name="RightWheelVisual">
        <pose>0 0 0 -1.57079632679 0 0</pose>
        <geometry>
          <cylinder>
            <length>0.01</length>
            <radius>0.03</radius>
          </cylinder>
        </geometry>
      </visual>
      <collision name="RightWheelCollision">
        <pose>0 0 0 -1.57079632679 0 0</pose>
        <geometry>
          <cylinder>
            <length>0.01</length>
            <radius>0.03</radius>
          </cylinder>
        </geometry>
        <surface>
          <friction>
            <ode>
              <mu>1.0</mu>
              <mu2>0.5</mu2>
              <fdir1>0 0 1</fdir1>
            </ode>
          </friction>
        </surface>
      </collision>
    </link>
    <link name="CenterWheel">
      <pose relative_to="CenterWheelJoint">0 0 0 0 0 0</pose>
      <inertial>
        <mass>.05</mass>
        <inertia>
          <ixx>0.00003331</ixx>
          <ixy>0</ixy>
          <ixz>0</ixz>
          <iyy>0.0000204</iyy>
          <iyz>0</iyz>
          <izz>0.0000204</izz>
        </inertia>
      </inertial>
      <gravity>true</gravity>
      <velocity_decay/>
      <visual name="CenterWheelVisual">
        <pose>0 0 0 -1.57079632679 0 0</pose>
        <geometry>
          <cylinder>
            <length>0.01</length>
            <radius>0.03</radius>
          </cylinder>
        </geometry>
      </visual>
      <collision name="CenterWheelCollision">
        <pose>0 0 0 -1.57079632679 0 0</pose>
        <geometry>
          <cylinder>
            <length>0.01</length>
            <radius>0.03</radius>
          </cylinder>
        </geometry>
        <surface>
          <friction>
            <ode>
              <mu>1.0</mu>
              <mu2>0.5</mu2>
              <fdir1>0 0 1</fdir1>
            </ode>
          </friction>
        </surface>
      </collision>
    </link>
    <link name="LeftWheel">
      <pose relative_to="LeftWheelJoint">0 0 0 0 0 0</pose>
      <inertial>
        <mass>.05</mass>
        <inertia>
          <ixx>0.00003331</ixx>
          <ixy>0</ixy>
          <ixz>0</ixz>
          <iyy>0.0000204</iyy>
          <iyz>0</iyz>
          <izz>0.0000204</izz>
        </inertia>
      </inertial>
      <gravity>true</gravity>
      <velocity_decay/>
      <visual name="LeftWheelVisual">
        <pose>0 0 0 -1.57079632679 0 0</pose>
        <geometry>
          <cylinder>
            <length>0.01</length>
            <radius>0.03</radius>
          </cylinder>
        </geometry>
      </visual>
      <collision name="LeftWheelCollision">
        <pose>0 0 0 -1.57079632679 0 0</pose>
        <geometry>
          <cylinder>
            <length>0.01</length>
            <radius>0.03</radius>
          </cylinder>
        </geometry>
        <surface>
          <friction>
            <ode>
              <mu>1.0</mu>
              <mu2>0.5</mu2>
              <fdir1>0 0 1</fdir1>
            </ode>
          </friction>
        </surface>
      </collision>
    </link>
    <joint name="LeftWheelJoint" type="revolute">
      <parent>base_link</parent>
      <child>LeftWheel</child>
      <pose relative_to="base_link">-0.405 -0.055 -0.085 0 0 -1.57</pose>
      <axis>
        <xyz>0 1 0</xyz>
        <limit>
          <lower>-1.79769e+308</lower>
          <upper>1.79769e+308</upper>
        </limit>
        <dynamics>
          <spring_reference>0</spring_reference>
          <spring_stiffness>0</spring_stiffness>
        </dynamics>
        <use_parent_model_frame>1</use_parent_model_frame>
      </axis>
    </joint>
    <joint name="RightWheelJoint" type="revolute">
      <parent>base_link</parent>
      <child>RightWheel</child>
      <pose relative_to="base_link">0.405 -0.055 -0.085 0 0 -1.57</pose>
      <axis>
        <xyz>0 1 0</xyz>
        <limit>
          <lower>-1.79769e+308</lower>
          <upper>1.79769e+308</upper>
        </limit>
        <dynamics>
          <spring_reference>0</spring_reference>
          <spring_stiffness>0</spring_stiffness>
        </dynamics>
        <use_parent_model_frame>1</use_parent_model_frame>
      </axis>
    </joint>
    <joint name="CenterWheelJoint" type="revolute">
      <parent>base_link</parent>
      <child>CenterWheel</child>
      <pose relative_to="base_link">0 0.351 -0.085 0 0 -1.57</pose>
      <axis>
        <xyz>0 1 0</xyz>
        <limit>
          <lower>-1.79769e+308</lower>
          <upper>1.79769e+308</upper>
        </limit>
        <dynamics>
          <spring_reference>0</spring_reference>
          <spring_stiffness>0</spring_stiffness>
        </dynamics>
        <use_parent_model_frame>1</use_parent_model_frame>
      </axis>
    </joint>
    <link name="aileron_left_link">
      <pose>-0.157 0.276 0.13 0 0 -1.67</pose>
      <visual name="visual_aileron_left_link">
        <geometry>
          <mesh>
            <uri>model://albatross/meshes/aileron_left.dae</uri>
          </mesh>
        </geometry>
      </visual>
      <collision name="collision_aileron_left_link">
        <geometry>
          <mesh>
            <uri>model://albatross/meshes/aileron_left.dae</uri>
          </mesh>
        </geometry>
      </collision>
      <inertial>
        <pose>0.0013926979950206766 -0.020256886992858734 -0.00084718131071825561 -1.5702649623555514 -1.4968622055264078 -1.5866465793244586</pose>
        <mass>0.69363462361421335</mass>
        <inertia>
          <ixx>0.011408993810042081</ixx>
          <ixy>0</ixy>
          <ixz>0</ixz>
          <iyy>0.011184896421525058</iyy>
          <iyz>0</iyz>
          <izz>0.0002419378408971488</izz>
        </inertia>
      </inertial>
    </link>
    <joint name="servo_0" type="revolute">
      <parent>base_link</parent>
      <child>aileron_left_link</child>
      <axis>
        <xyz>-1 0 0</xyz>
        <limit>
          <lower>-0.53</lower>
          <upper>0.53</upper>
        </limit>
        <dynamics>
          <spring_reference>0</spring_reference>
          <spring_stiffness>0</spring_stiffness>
        </dynamics>
        <use_parent_model_frame>1</use_parent_model_frame>
      </axis>
    </joint>
    <link name="aileron_right_link">
      <pose>-0.157 -0.276 0.13 0 0 -1.473</pose>
      <visual name="visual_aileron_right_link">
        <geometry>
          <mesh>
            <uri>model://albatross/meshes/aileron_right.dae</uri>
          </mesh>
        </geometry>
      </visual>
      <collision name="collision_aileron_right_link">
        <geometry>
          <mesh>
            <uri>model://albatross/meshes/aileron_right.dae</uri>
          </mesh>
        </geometry>
      </collision>
      <inertial>
        <pose>-0.0013927001631649414 -0.020256886759491138 -0.00084718303942941605 -1.5713276505282008 -1.496862114877646 -1.5549461086906684</pose>
        <mass>0.69363463531782987</mass>
        <inertia>
          <ixx>0.011408994031789375</ixx>
          <ixy>0</ixy>
          <ixz>0</ixz>
          <iyy>0.011184896645700647</iyy>
          <iyz>0</iyz>
          <izz>0.00024193783975385642</izz>
        </inertia>
      </inertial>
    </link>
    <joint name="servo_1" type="revolute">
      <parent>base_link</parent>
      <child>aileron_right_link</child>
      <axis>
        <xyz>-1 0 0</xyz>
        <limit>
          <lower>-0.53</lower>
          <upper>0.53</upper>
        </limit>
        <dynamics>
          <spring_reference>0</spring_reference>
          <spring_stiffness>0</spring_stiffness>
        </dynamics>
        <use_parent_model_frame>1</use_parent_model_frame>
      </axis>
    </joint>
    <link name="rudder_left_link">
      <pose>-1.283 0.17 0.212 1.57 -0.39905911111 -2.013664556</pose>
      <visual name="visual_rudder_left_link">
        <geometry>
          <mesh>
            <uri>model://albatross/meshes/rudder_left.dae</uri>
          </mesh>
        </geometry>
      </visual>
      <collision name="collision_rudder_left_link">
        <geometry>
          <mesh>
            <uri>model://albatross/meshes/rudder_left.dae</uri>
          </mesh>
        </geometry>
      </collision>
      <inertial>
        <pose>0.0086659258447588771 -0.0034581440980500826 0.011993788874177187 1.5723926276260292 -0.18945174289552996 1.5667283795418694</pose>
        <mass>0.16659999435205503</mass>
        <inertia>
          <ixx>0.0010555073514094649</ixx>
          <ixy>0</ixy>
          <ixz>0</ixz>
          <iyy>0.0010404851349077506</iyy>
          <iyz>0</iyz>
          <izz>1.723734714341286e-05</izz>
        </inertia>
      </inertial>
    </link>
    <joint name="rudder_left_joint" type="revolute">
      <parent>base_link</parent>
      <child>rudder_left_link</child>
      <axis>
        <xyz>1 0 0</xyz>
        <limit>
          <lower>0</lower>
          <upper>0</upper>
          <effort>0</effort>
          <velocity>0</velocity>
        </limit>
        <dynamics>
          <spring_reference>0</spring_reference>
          <spring_stiffness>0</spring_stiffness>
        </dynamics>
        <use_parent_model_frame>1</use_parent_model_frame>
      </axis>
    </joint>
    <link name="rudder_right_link">
      <pose>-1.283 -0.17  0.212 1.57 0.39905911111 -1.126335444</pose>
      <visual name="visual_rudder_right_link">
        <geometry>
          <mesh>
            <uri>model://albatross/meshes/rudder_right.dae</uri>
          </mesh>
        </geometry>
      </visual>
      <collision name="collision_rudder_right_link">
        <geometry>
          <mesh>
            <uri>model://albatross/meshes/rudder_right.dae</uri>
          </mesh>
        </geometry>
      </collision>
      <inertial>
        <pose>-0.0086659165291879357 -0.003458124410117001 0.011993796077636124 1.5691999396168039 -0.18945218003724901 1.5748643595746579</pose>
        <mass>0.1665997119700709</mass>
        <inertia>
          <ixx>0.0010555055074389123</ixx>
          <ixy>0</ixy>
          <ixz>0</ixz>
          <iyy>0.0010404833188929115</iyy>
          <iyz>0</iyz>
          <izz>1.7237308824860217e-05</izz>
        </inertia>
      </inertial>
    </link>
    <joint name="rudder_right_joint" type="revolute">
      <parent>base_link</parent>
      <child>rudder_right_link</child>
      <axis>
        <xyz>1 0 0</xyz>
        <limit>
          <lower>0</lower>
          <upper>0</upper>
          <effort>0</effort>
          <velocity>0</velocity>
        </limit>
        <dynamics>
          <spring_reference>0</spring_reference>
          <spring_stiffness>0</spring_stiffness>
        </dynamics>
        <use_parent_model_frame>1</use_parent_model_frame>
      </axis>
    </joint>
    <link name="elevator">
      <inertial>
        <mass>0.00000001</mass>
        <inertia>
          <ixx>0.000001</ixx>
          <ixy>0.0</ixy>
          <iyy>0.000001</iyy>
          <ixz>0.0</ixz>
          <iyz>0.0</iyz>
          <izz>0.000001</izz>
        </inertia>
        <pose> -0.5 0 0 0.00 0 0.0</pose>
      </inertial>
    </link>
    <joint name='servo_2' type='revolute'>
      <parent>base_link</parent>
      <child>elevator</child>
      <pose>-1.283 0 0.212 0 0 0</pose>
      <axis>
        <xyz>0 -1 0</xyz>
        <limit>
          <!-- -30/+30 deg. -->
          <lower>-0.53</lower>
          <upper>0.53</upper>
        </limit>
        <dynamics>
          <damping>1.000</damping>
        </dynamics>
      </axis>
      <physics>
        <ode>
          <implicit_spring_damper>1</implicit_spring_damper>
        </ode>
      </physics>
    </joint>
    <link name="rotor_1">
      <gravity>true</gravity>
      <self_collide>false</self_collide>
      <velocity_decay/>
      <pose>-0.31 0 0.118 4.71 0 -1.57</pose>
      <inertial>
          <mass>0.016076923076923075</mass>
          <inertia>
            <ixx>3.8464910483993325e-07</ixx>
            <iyy>2.6115851691700804e-05</iyy>
            <izz>2.649858234714004e-05</izz>
          </inertia>
        </inertial>
      <visual name="rotor_1_visual">
        <pose>0 0 0 -3.14 0 0</pose>
        <geometry>
          <mesh>
            <uri>model://albatross/meshes/propeller_cw.dae</uri>
          </mesh>
        </geometry>
      </visual>
      <collision name="rotor_1_collision">
        <geometry>
          <box>
            <size>0.2792307692307692 0.016923076923076923 0.0008461538461538462</size>
          </box>
        </geometry>
        <surface>
          <contact>
            <ode>
              <min_depth>0.001</min_depth>
              <max_vel>0</max_vel>
            </ode>
          </contact>
          <friction>
            <ode/>
          </friction>
        </surface>
      </collision>
    </link>
    <joint name="rotor_1_joint" type="revolute">
      <parent>base_link</parent>
      <child>rotor_1</child>
      <axis>
        <xyz>0 0 1</xyz>
        <limit>
          <lower>-1e+16</lower>
          <upper>1e+16</upper>
        </limit>
        <dynamics>
          <spring_reference>0</spring_reference>
          <spring_stiffness>0</spring_stiffness>
        </dynamics>
        <use_parent_model_frame>1</use_parent_model_frame>
      </axis>
    </joint>
    <plugin filename="gz-sim-lift-drag-system" name="gz::sim::systems::LiftDrag">
      <a0>0.05984281113</a0>
      <cla>4.752798721</cla>
      <cda>0.6417112299</cda>
      <cma>0.0</cma>
      <alpha_stall>0.3391428111</alpha_stall>
      <cla_stall>-3.85</cla_stall>
      <cda_stall>-0.9233984055</cda_stall>
      <cma_stall>0</cma_stall>
      <cp>-0.05 0.45 0.05</cp>
      <area>0.6</area>
      <air_density>1.2041</air_density>
      <forward>1 0 0</forward>
      <upward>0 0 1</upward>
      <link_name>base_link</link_name>
      <control_joint_name>servo_0</control_joint_name>
      <control_joint_rad_to_cl>-0.3</control_joint_rad_to_cl>
    </plugin>
    <plugin
      filename="gz-sim-joint-position-controller-system" name="gz::sim::systems::JointPositionController">
      <joint_name>servo_0</joint_name>
      <sub_topic>servo_0</sub_topic>
      <p_gain>10.0</p_gain>
    </plugin>
    <plugin filename="gz-sim-lift-drag-system" name="gz::sim::systems::LiftDrag">
      <a0>0.05984281113</a0>
      <cla>4.752798721</cla>
      <cda>0.6417112299</cda>
      <cma>0.0</cma>
      <alpha_stall>0.3391428111</alpha_stall>
      <cla_stall>-3.85</cla_stall>
      <cda_stall>-0.9233984055</cda_stall>
      <cma_stall>0</cma_stall>
      <cp>-0.05 -0.45 0.05</cp>
      <area>0.6</area>
      <air_density>1.2041</air_density>
      <forward>1 0 0</forward>
      <upward>0 0 1</upward>
      <link_name>base_link</link_name>
      <control_joint_name>servo_1</control_joint_name>
      <control_joint_rad_to_cl>-0.3</control_joint_rad_to_cl>
    </plugin>
    <plugin
      filename="gz-sim-joint-position-controller-system" name="gz::sim::systems::JointPositionController">
      <joint_name>servo_1</joint_name>
      <sub_topic>servo_1</sub_topic>
      <p_gain>10.0</p_gain>
    </plugin>
    <plugin filename="gz-sim-lift-drag-system" name="gz::sim::systems::LiftDrag">
      <a0>-0.2</a0>
      <cla>4.752798721</cla>
      <cda>0.6417112299</cda>
      <cma>0.0</cma>
      <alpha_stall>0.3391428111</alpha_stall>
      <cla_stall>-3.85</cla_stall>
      <cda_stall>-0.9233984055</cda_stall>
      <cma_stall>0</cma_stall>
      <cp>-0.5 0 0</cp>
      <area>0.01</area>
      <air_density>1.2041</air_density>
      <forward>1 0 0</forward>
      <upward>0 0 1</upward>
      <link_name>base_link</link_name>
      <control_joint_name>servo_2</control_joint_name>
      <control_joint_rad_to_cl>-4.0</control_joint_rad_to_cl>
    </plugin>
    <plugin
      filename="gz-sim-joint-position-controller-system" name="gz::sim::systems::JointPositionController">
      <joint_name>servo_2</joint_name>
      <sub_topic>servo_2</sub_topic>
      <p_gain>10.0</p_gain>
    </plugin>
    <plugin filename="gz-sim-lift-drag-system" name="gz::sim::systems::LiftDrag">
      <a0>0.0</a0>
      <cla>4.752798721</cla>
      <cda>0.6417112299</cda>
      <cma>0.0</cma>
      <alpha_stall>0.3391428111</alpha_stall>
      <cla_stall>-3.85</cla_stall>
      <cda_stall>-0.9233984055</cda_stall>
      <cma_stall>0</cma_stall>
      <cp>-0.5 0 0.05</cp>
      <area>0.02</area>
      <air_density>1.2041</air_density>
      <forward>1 0 0</forward>
      <upward>0 1 0</upward>
      <link_name>base_link</link_name>
      <control_joint_name>rudder_left_joint</control_joint_name>
      <control_joint_rad_to_cl>0.8</control_joint_rad_to_cl>
    </plugin>
    <plugin filename="gz-sim-lift-drag-system" name="gz::sim::systems::LiftDrag">
      <a0>0.0</a0>
      <cla>4.752798721</cla>
      <cda>0.6417112299</cda>
      <cma>0.0</cma>
      <alpha_stall>0.3391428111</alpha_stall>
      <cla_stall>-3.85</cla_stall>
      <cda_stall>-0.9233984055</cda_stall>
      <cma_stall>0</cma_stall>
      <cp>-0.5 0 0.05</cp>
      <area>0.02</area>
      <air_density>1.2041</air_density>
      <forward>1 0 0</forward>
      <upward>0 1 0</upward>
      <link_name>base_link</link_name>
      <control_joint_name>rudder_right_joint</control_joint_name>
      <control_joint_rad_to_cl>0.8</control_joint_rad_to_cl>
    </plugin>
    <plugin filename="ignition-gazebo-multicopter-motor-model-system" name="gz::sim::systems::MulticopterMotorModel">
      <jointName>rotor_1_joint</jointName>
      <linkName>rotor_1</linkName>
      <turningDirection>ccw</turningDirection>
      <timeConstantUp>0.0125</timeConstantUp>
      <timeConstantDown>0.025</timeConstantDown>
      <maxRotVelocity>1000</maxRotVelocity>
      <motorConstant>2.44858e-05</motorConstant>
      <momentConstant>0.016</momentConstant>
      <commandSubTopic>command/motor_speed</commandSubTopic>
      <motorNumber>0</motorNumber>
      <rotorDragCoefficient>8.06428e-05</rotorDragCoefficient>
      <rollingMomentCoefficient>1e-06</rollingMomentCoefficient>
      <rotorVelocitySlowdownSim>10</rotorVelocitySlowdownSim>
      <motorType>velocity</motorType>
    </plugin>
  </model>
</sdf>
